Workbook

Sheet Form Responses 1
A1: Timestamp | B1: Nama / Perusahaan | C1: Alamat | D1: No. Telp./HP (tulis dengan format 08xxx) | E1: Jenis Pesanan | F1: Jenis UTTP | G1: Merk (Jika tidak ada isi -) | H1: Tipe (Jika tidak ada isi -) | I1: No. Seri (Jika tidak ada isi -) | J1: Kapasitas / Skala Terkecil (tuliskan satuan kg/g) | K1: Upload foto UTTP (sebelum pengujian)
A2: 46028.606 | B2: Apotek Wijoyo Kusumo | C2: Jl. Kutoarjo KM 2, Jatisari, Kecamatan Kebumen, Kabupaten Kebumen | D2: 081328252683 | E2: Tera Ulang | F2: Timbangan Elektronik | G2: ACIS | H2: BC 500 | I2: E241203145 | J2: 500 g / 0,1 g | K2: https://drive.google.com/open?id=1nJTfGHX9zoXwQwQrtmCbRod64GKJ63iQ
A3: 46029.362 | B3: PT. Karya Adi Kencana | C3: Jl. Raya Tembana Peniron No.1, Desa Karangpoh, Kecamatan Pejagoan, Kabupaten Kebumen | D3: 081805863292 | E3: Tera | F3: Timbangan Elektronik | G3: SONIC | H3: A12E | I3: IMI23019437 | J3: 6000 kg / 1 kg
A4: 46029.369 | B4: PT. Karya Adi Kencana, | C4: Jl. Raya Tembana Peniron No.1, Desa Karangpoh, Kecamatan Pejagoan, Kabupaten Kebumen | D4: 081805863292 | E4: Tera Ulang | F4: Timbangan Elektronik | G4: OMRON | H4: K3HB VLC | I4: - | J4: 5000 kg / 1 kg
A5: 46029.37 | B5: PT. Karya Adi Kencana,, | C5: Jl. Raya Tembana Peniron No.1, Desa Karangpoh, Kecamatan Pejagoan, Kabupaten Kebumen | D5: 081805863292 | E5: Tera Ulang | F5: Timbangan Elektronik | G5: OMRON | H5: K3HB VLC | I5: - | J5: 2000 kg / 1 kg
A6: 46029.371 | B6: PT. Karya Adi Kencana,,, | C6: Jl. Raya Tembana Peniron No.1, Desa Karangpoh, Kecamatan Pejagoan, Kabupaten Kebumen | D6: 081805863292 | E6: Tera Ulang | F6: Timbangan Elektronik | G6: OMRON | H6: K3HB VLC | I6: - | J6: 2000 kg / 1 kg
A7: 46029.372 | B7: PT. Karya Adi Kencana. | C7: Jl. Raya Tembana Peniron No.1, Desa Karangpoh, Kecamatan Pejagoan, Kabupaten Kebumen | D7: 081805863292 | E7: Tera Ulang | F7: Timbangan Elektronik | G7: WEIGHING INDICATOR | H7: AC 9000 | I7: - | J7: 4000 kg / 2 kg
A8: 46029.373 | B8: PT. Karya Adi Kencana.. | C8: Jl. Raya Tembana Peniron No.1, Desa Karangpoh, Kecamatan Pejagoan, Kabupaten Kebumen | D8: 081805863292 | E8: Tera Ulang | F8: Timbangan Elektronik | G8: GREAT SCALE | H8: A12E | I8: IMIWH9-1909000758 | J8: 1000 kg / 1 kg
A9: 46029.374 | B9: PT. Karya Adi Kencana... | C9: Jl. Raya Tembana Peniron No.1, Desa Karangpoh, Kecamatan Pejagoan, Kabupaten Kebumen | D9: 081805863292 | E9: Tera Ulang | F9: Timbangan Elektronik | G9: GREAT SCALE | H9: A12E | I9: A12E2206008 | J9: 3000 kg / 0,5 kg
A10: 46029.39 | B10: SPBU 44.543.04 PT. Tawakal Tsani Makmur | C10: Jl. Yos Sudarso no 122, Desa Wero, Kec. Gombong, Kab. Kebumen | D10: 085310753455 | E10: Tera Ulang | F10: PU BBM | G10: Gilbarco | H10: B21 | I10: HEPA 097853 | J10: - | K10: https://drive.google.com/open?id=1kXX2vYchhm5UmtUU_WUI4nMnhloPP0Aa
A11: 46029.417 | B11: SPBU 44.543.04 PT. Tawakal Tsani Makmur. | C11: Jl. Yos Sudarso no 122, Desa Wero, Kec. Gombong, Kab. Kebumen | D11: 085310753455 | E11: Tera Ulang | F11: PU BBM | G11: Gilbarco | H11: B21 | I11: KDPA 028431 | J11: - | K11: https://drive.google.com/open?id=1555aEwhqvxa1aDE5zpvOtJl4raixXIa8
A12: 46029.425 | B12: KPH KEDU SELATAN | C12: Jl. A. Yani No 23 Purworejo | D12: 81390175776 | E12: Tera Ulang | F12: Dacin | G12: SNS | H12: - | I12: 211006 | J12: 110 kg / 500 g
A13: 46029.426 | B13: KPH KEDU SELATAN. | C13: Jl. A. Yani No 23 Purworejo | D13: 81390175776 | E13: Tera Ulang | F13: Dacin | G13: SNS | H13: - | I13: 211081 | J13: 110 kg / 500 g
A14: 46029.427 | B14: KPH KEDU SELATAN.. | C14: Jl. A. Yani No 23 Purworejo | D14: 81390175776 | E14: Tera Ulang | F14: Dacin | G14: SNS | H14: - | I14: 170694 | J14: 110 kg / 500 g
A15: 46029.428 | B15: KPH KEDU SELATAN... | C15: Jl. A. Yani No 23 Purworejo | D15: 81390175776 | E15: Tera Ulang | F15: Dacin | G15: SNS | H15: - | I15: 111724 | J15: 110 kg / 500 g
A16: 46029.43 | B16: KPH KEDU SELATAN, | C16: Jl. A. Yani No 23 Purworejo | D16: 81390175776 | E16: Tera Ulang | F16: Timbangan Sentisimal | G16: Armada | H16: - | I16: 97815 | J16: 500 kg / 200 g
A17: 46029.433 | B17: KPH KEDU SELATAN,, | C17: Jl. A. Yani No 23 Purworejo | D17: 81390175776 | E17: Tera Ulang | F17: Timbangan Sentisimal | G17: Intra | H17: - | I17: - | J17: 300 kg / 100 g
A18: 46029.435 | B18: KPH KEDU SELATAN | C18: Jl. A. Yani No 23 Purworejo | D18: 81390175776 | E18: Tera Ulang | F18: Anak Timbangan | G18: - | H18: - | I18: - | J18: 4 buah
A19: 46029.441 | B19: SPBU 44.543.04 PT. Tawakal Tsani Makmur.. | C19: Jl. Yos Sudarso no 122, Desa Wero, Kec. Gombong, Kab. Kebumen | D19: 085310753455 | E19: Tera Ulang | F19: PU BBM | G19: Wayne | H19: 2203/Akswz5/E | I19: G 07118 | J19: - | K19: https://drive.google.com/open?id=1mp3uCerbHyp2IuCz2jU4hpmA339EJS1Z
A20: 46029.455 | B20: SPBU 44.543.04 PT. Tawakal Tsani Makmur... | C20: Jl. Yos Sudarso no 122, Desa Wero, Kec. Gombong, Kab. Kebumen | D20: 085310753455 | E20: Tera Ulang | F20: PU BBM | G20: Gilbarco | H20: B21 | I20: HEPA 097463 | J20: - | K20: https://drive.google.com/open?id=1TBFTWqjf-Q5mXJRgy3aJLNcWOo1dhICZ
A21: 46030.344 | B21: Bank BSI Kebumen | C21: Jl. HM Sarbini 201 A | D21: 085876458949 | E21: Tera Ulang | F21: Timbangan Elektronik | G21: SHIMADZU | H21: UX3200G | I21: D461741786 | J21: 3200 g/ 0,01 g | K21: https://drive.google.com/open?id=1L-jc1J5LFMdfcQ4XCjR4clElpPum4xh7
A22: 46030.352 | B22: Chayati | C22: Kawedusan, Kebumen | D22: 0882003225955 | E22: Tera Ulang | F22: Timbangan Sentisimal | G22: SSS | H22: - | I22: 15492 | J22: 300 kg / 100 g
A23: 46030.36 | B23: Apotek Padureso | C23: Jl. Wadaslintang km 17 Pasar pon, Padureso, Kebumen | D23: 081393921128 | E23: Tera Ulang | F23: Timbangan Elektronik | G23: Acis | H23: Bc500 | I23: C220801736 | J23: 500 g /0,1 g | K23: https://drive.google.com/open?id=1IpSWfG6TZrBP0SaxKPudO1sU4wZI8MqV
A24: 46030.368 | B24: Toko Mas Niaga | C24: Pasar Wonokriyo Blok F no. 14 Gombong Kebumen | D24: 082220147807 | E24: Tera Ulang | F24: Timbangan Elektronik | G24: AND | H24: HL-100 | I24: K0003H2110724 | J24: 100 g / 0.01 g
A25: 46030.369 | B25: Toko Mas Niaga. | C25: Pasar Wonokriyo Blok F no. 14 Gombong Kebumen | D25: 082220147807 | E25: Tera Ulang | F25: Timbangan Elektronik | G25: AND | H25: HL-100 | I25: K0004H804001193 | J25: 100 g / 0.01 g
A26: 46030.37 | B26: Toko Mas Niaga.. | C26: Pasar Wonokriyo Blok F no. 14 Gombong Kebumen | D26: 082220147807 | E26: Tera Ulang | F26: Timbangan Elektronik | G26: AND | H26: EK-410i | I26: 6A4443221 | J26: 400 g / 0.01 g
A27: 46030.372 | B27: Toko Mas Niaga, | C27: Pasar Tumenggungan Blok A 9-10 kebumen | D27: 082220147807 | E27: Tera Ulang | F27: Timbangan Elektronik | G27: AND | H27: HT-120 | I27: 5171100070 | J27: 120 g / 0.01 g
A28: 46030.373 | B28: Toko Mas Niaga,, | C28: Pasar Tumenggungan Blok A 9-10 kebumen | D28: 082220147807 | E28: Tera Ulang | F28: Timbangan Elektronik | G28: AND | H28: EK-410i | I28: 6A4443254 | J28: 400 g / 0.01 g
A29: 46030.377 | B29: Toko Mas Niaga' | C29: Jln Yos Sudarso 331 Gombong | D29: 082220147807 | E29: Tera Ulang | F29: Timbangan Elektronik | G29: AND | H29: HT-120 | I29: 5150900175 | J29: 120 g / 0.01 g
A30: 46030.378 | B30: Toko Mas Niaga'' | C30: Jln Yos Sudarso 331 Gombong | D30: 082220147807 | E30: Tera Ulang | F30: Timbangan Elektronik | G30: AND | H30: HT-120 | I30: 5210900407 | J30: 120 g / 0.01 g
A31: 46030.378 | B31: Toko Mas Niaga''' | C31: Jln Yos Sudarso 331 Gombong | D31: 082220147807 | E31: Tera Ulang | F31: Timbangan Elektronik | G31: AND | H31: EK-410i | I31: 6A4443222 | J31: 400 g / 0.01 g
A32: 46030.394 | B32: SPBU 43.543.12 PT. Putra Ramadhan | C32: Jl. HM Sarbini, Kelurahan Bumirejo, Kecamatan Kebumen, Kabupaten Kebumen | D32: 085325466920 | E32: Tera Ulang | F32: PU BBM | G32: Gilbarco | H32: NA1S500 | I32: EN 00015183 | J32: 60 Lpm / 5 lpm | K32: https://drive.google.com/open?id=1he6D8G1_RM0qogQ-3M0fNVOs0PA4uJcn
A33: 46030.438 | B33: SPBU 43.543.12 PT. Putra Ramadhan. | C33: Jl. HM Sarbini, Kelurahan Bumirejo, Kecamatan Kebumen, Kabupaten Kebumen | D33: 085325466920 | E33: Tera Ulang | F33: PU BBM | G33: Gilbarco | H33: NA2 | I33: AAEN240478 | J33: 60 lpm / 5 lpm | K33: https://drive.google.com/open?id=1_OeWkQ8c51jM9raXvXIgfcsqrF90ufxm
A34: 46030.48 | B34: SPBU 43.543.12 PT. Putra Ramadhan.. | C34: Jl. HM Sarbini, Kelurahan Bumirejo, Kecamatan Kebumen, Kabupaten Kebumen | D34: 085325466920 | E34: Tera Ulang | F34: PU BBM | G34: Gilbarco | H34: NA2 | I34: MXEN240026 | J34: 60 lpm / 5 lpm | K34: https://drive.google.com/open?id=1wznJdK-bAw0v4k7Z7WE2OhDOsJay_K87
A35: 46030.505 | B35: SPBU 43.543.12 PT. Putra Ramadhan... | C35: Jl. HM Sarbini, Kelurahan Bumirejo, Kecamatan Kebumen, Kabupaten Kebumen | D35: 085325466920 | E35: Tera Ulang | F35: PU BBM | G35: Gilbarco | H35: NA1 | I35: ABEN273664 | J35: 60 lpm/5lpm | K35: https://drive.google.com/open?id=1iUJwd2oR4YoTL5pqS7Ct5uSuVm9CtghP
A36: 46030.561 | B36: Apotek Pandya 16 | C36: Jatinegara , Sempor | D36: 087774582080 | E36: Tera Ulang | F36: Timbangan Elektronik | G36: CHQ | H36: DJ602C | J36: 600 gr/0,01 gr | K36: https://drive.google.com/open?id=1JFtZ518exguix0W4t5bL2fkYkGX_cjFa
A37: 46031.494 | B37: APOTEK TAHER FARMA PETANAHAN | C37: Jl. Sokka Petanahan No. 217, Jogomertan, Kec. Petanahan, Kabupaten Kebumen | D37: 087738517431 | E37: Tera Ulang | F37: Timbangan Elektronik | G37: ACIS | H37: BC - 5000 | I37: E2504031124 | J37: 5000 g / 1 g | K37: https://drive.google.com/open?id=1lHQRriaGyFUWOWwTdgBW_jrJJEH9LB_t
A38: 46031.796 | B38: SPBU 44.543.22 (PT. Wahyu Putra Sejati) | C38: Desa Tambakmulyo, Kecamatan Puring, Kabupaten Kebumen | D38: 081805863292 | E38: Tera Ulang | F38: PU BBM | G38: TATSUNO | H38: SSB3662 | I38: AA315408 2022-1 | J38: 65 L/min | K38: https://drive.google.com/open?id=1IhJxJsx553ITw9JNq77FH2MY_4RIToPJ
A39: 46031.799 | B39: SPBU 44.543.10 (CV. Dewi Bulan) | C39: Jl. Lingkar Soka, Desa Kewayuhan, Kecamatan Pejagoan, Kabupaten Kebumen | D39: 081805863292 | E39: Tera Ulang | F39: PU BBM | G39: TATSUNO | H39: GSB 2441P | I39: AA 192403 2010-6 | J39: 60 L/min | K39: https://drive.google.com/open?id=1_yP5vWr6nqx0erMdq021Q8f736t8Fnzr
A40: 46031.802 | B40: SPBU 44.543.10 (CV. Dewi Bulan), | C40: Jl. Lingkar Soka, Desa Kewayuhan, Kecamatan Pejagoan, Kabupaten Kebumen | D40: 081805863292 | E40: Tera Ulang | F40: PU BBM | G40: TATSUNO | H40: GSB 2441P | I40: AA 199109 2011-3 | J40: 60 L/min | K40: https://drive.google.com/open?id=1zJU6lfy5LgaFy4U-lmHH-8o31eC-LyLH
...

Sheet MASTER SKHP 2026
B1: SKHP | D1: Nama Pemilik | E1: Alamat | F1: Jenis UTTP | G1: Merk | H1: UTTP | K1: Tanggal Uji | L1: Cap Tanda Tera | M1: Keterangan
B2: Nomor | C2: Tanggal | H2: Type | I2: Seri | J2: Kapasitas/DB
A3: 1 | B3: TE-001/I/500.2.3.15/3/2026 | C3: 46028 | D3: Apotek Wijoyo Kusumo | E3: =VLOOKUP(D3,'Form Responses 1'!B:J,2,FALSE) -> Jl. Kutoarjo KM 2, Jatisari, Kecamatan Kebumen, Kabupaten Kebumen | F3: =VLOOKUP(D3,'Form Responses 1'!B:J,5,FALSE) -> Timbangan Elektronik | G3: =VLOOKUP(D3,'Form Responses 1'!B:J,6,FALSE) -> ACIS | H3: =VLOOKUP(D3,'Form Responses 1'!B:J,7,FALSE) -> BC 500 | I3: =VLOOKUP(D3,'Form Responses 1'!B:J,8,FALSE) -> E241203145 | J3: =VLOOKUP(D3,'Form Responses 1'!B:J,9,FALSE) -> 500 g / 0,1 g | K3: 46028 | L3: SL6 (26) | M3: TRUE
A4: 2 | B4: TE-002/I/500.2.3.15/6/2026 | C4: 46029 | D4: PT. Karya Adi Kencana | E4: =VLOOKUP(D4,'Form Responses 1'!B:J,2,FALSE) -> Jl. Raya Tembana Peniron No.1, Desa Karangpoh, Kecamatan Pejagoan, Kabupaten Kebumen | F4: =VLOOKUP(D4,'Form Responses 1'!B:J,5,FALSE) -> Timbangan Elektronik | G4: =VLOOKUP(D4,'Form Responses 1'!B:J,6,FALSE) -> SONIC | H4: =VLOOKUP(D4,'Form Responses 1'!B:J,7,FALSE) -> A12E | I4: =VLOOKUP(D4,'Form Responses 1'!B:J,8,FALSE) -> IMI23019437 | J4: =VLOOKUP(D4,'Form Responses 1'!B:J,9,FALSE) -> 6000 kg / 1 kg | K4: 46028 | L4: SL4 (26) | M4: TRUE
A5: 3 | B5: TE-003/I/500.2.3.15/7/2026 | C5: 46029 | D5: PT. Karya Adi Kencana, | E5: =VLOOKUP(D5,'Form Responses 1'!B:J,2,FALSE) -> Jl. Raya Tembana Peniron No.1, Desa Karangpoh, Kecamatan Pejagoan, Kabupaten Kebumen | F5: =VLOOKUP(D5,'Form Responses 1'!B:J,5,FALSE) -> Timbangan Elektronik | G5: =VLOOKUP(D5,'Form Responses 1'!B:J,6,FALSE) -> OMRON | H5: =VLOOKUP(D5,'Form Responses 1'!B:J,7,FALSE) -> K3HB VLC | I5: =VLOOKUP(D5,'Form Responses 1'!B:J,8,FALSE) -> - | J5: =VLOOKUP(D5,'Form Responses 1'!B:J,9,FALSE) -> 5000 kg / 1 kg | K5: 46028 | L5: SP6 (26) | M5: TRUE
D6: PT. Karya Adi Kencana,, | E6: =VLOOKUP(D6,'Form Responses 1'!B:J,2,FALSE) -> Jl. Raya Tembana Peniron No.1, Desa Karangpoh, Kecamatan Pejagoan, Kabupaten Kebumen | F6: =VLOOKUP(D6,'Form Responses 1'!B:J,5,FALSE) -> Timbangan Elektronik | G6: =VLOOKUP(D6,'Form Responses 1'!B:J,6,FALSE) -> OMRON | H6: =VLOOKUP(D6,'Form Responses 1'!B:J,7,FALSE) -> K3HB VLC | I6: =VLOOKUP(D6,'Form Responses 1'!B:J,8,FALSE) -> - | J6: =VLOOKUP(D6,'Form Responses 1'!B:J,9,FALSE) -> 2000 kg / 1 kg | L6: SP6 (26) | M6: TRUE
D7: PT. Karya Adi Kencana,,, | E7: =VLOOKUP(D7,'Form Responses 1'!B:J,2,FALSE) -> Jl. Raya Tembana Peniron No.1, Desa Karangpoh, Kecamatan Pejagoan, Kabupaten Kebumen | F7: =VLOOKUP(D7,'Form Responses 1'!B:J,5,FALSE) -> Timbangan Elektronik | G7: =VLOOKUP(D7,'Form Responses 1'!B:J,6,FALSE) -> OMRON | H7: =VLOOKUP(D7,'Form Responses 1'!B:J,7,FALSE) -> K3HB VLC | I7: =VLOOKUP(D7,'Form Responses 1'!B:J,8,FALSE) -> - | J7: =VLOOKUP(D7,'Form Responses 1'!B:J,9,FALSE) -> 2000 kg / 1 kg | L7: SP6 (26) | M7: TRUE
A8: 4 | B8: TE-004/I/500.2.3.15/8/2026 | C8: 46029 | D8: PT. Karya Adi Kencana. | E8: =VLOOKUP(D8,'Form Responses 1'!B:J,2,FALSE) -> Jl. Raya Tembana Peniron No.1, Desa Karangpoh, Kecamatan Pejagoan, Kabupaten Kebumen | F8: =VLOOKUP(D8,'Form Responses 1'!B:J,5,FALSE) -> Timbangan Elektronik | G8: =VLOOKUP(D8,'Form Responses 1'!B:J,6,FALSE) -> WEIGHING INDICATOR | H8: =VLOOKUP(D8,'Form Responses 1'!B:J,7,FALSE) -> AC 9000 | I8: =VLOOKUP(D8,'Form Responses 1'!B:J,8,FALSE) -> - | J8: =VLOOKUP(D8,'Form Responses 1'!B:J,9,FALSE) -> 4000 kg / 2 kg | K8: 46028 | L8: SP6 (26) | M8: TRUE
D9: PT. Karya Adi Kencana.. | E9: =VLOOKUP(D9,'Form Responses 1'!B:J,2,FALSE) -> Jl. Raya Tembana Peniron No.1, Desa Karangpoh, Kecamatan Pejagoan, Kabupaten Kebumen | F9: =VLOOKUP(D9,'Form Responses 1'!B:J,5,FALSE) -> Timbangan Elektronik | G9: =VLOOKUP(D9,'Form Responses 1'!B:J,6,FALSE) -> GREAT SCALE | H9: =VLOOKUP(D9,'Form Responses 1'!B:J,7,FALSE) -> A12E | I9: =VLOOKUP(D9,'Form Responses 1'!B:J,8,FALSE) -> IMIWH9-1909000758 | J9: =VLOOKUP(D9,'Form Responses 1'!B:J,9,FALSE) -> 1000 kg / 1 kg | L9: SP6 (26) | M9: TRUE
D10: PT. Karya Adi Kencana... | E10: =VLOOKUP(D10,'Form Responses 1'!B:J,2,FALSE) -> Jl. Raya Tembana Peniron No.1, Desa Karangpoh, Kecamatan Pejagoan, Kabupaten Kebumen | F10: =VLOOKUP(D10,'Form Responses 1'!B:J,5,FALSE) -> Timbangan Elektronik | G10: =VLOOKUP(D10,'Form Responses 1'!B:J,6,FALSE) -> GREAT SCALE | H10: =VLOOKUP(D10,'Form Responses 1'!B:J,7,FALSE) -> A12E | I10: =VLOOKUP(D10,'Form Responses 1'!B:J,8,FALSE) -> A12E2206008 | J10: =VLOOKUP(D10,'Form Responses 1'!B:J,9,FALSE) -> 3000 kg / 0,5 kg | L10: SP6 (26) | M10: TRUE
A11: 5 | B11: DL-001/I/500.2.3.15/9/2026 | C11: 46029 | D11: KPH KEDU SELATAN | E11: =VLOOKUP(D11,'Form Responses 1'!B:J,2,FALSE) -> Jl. A. Yani No 23 Purworejo | F11: =VLOOKUP(D11,'Form Responses 1'!B:J,5,FALSE) -> Dacin | G11: =VLOOKUP(D11,'Form Responses 1'!B:J,6,FALSE) -> SNS | H11: =VLOOKUP(D11,'Form Responses 1'!B:J,7,FALSE) -> - | I11: =VLOOKUP(D11,'Form Responses 1'!B:J,8,FALSE) -> 211006 | J11: =VLOOKUP(D11,'Form Responses 1'!B:J,9,FALSE) -> 110 kg / 500 g | K11: 46029 | L11: SL4 (26) | M11: TRUE
D12: KPH KEDU SELATAN. | E12: =VLOOKUP(D12,'Form Responses 1'!B:J,2,FALSE) -> Jl. A. Yani No 23 Purworejo | F12: =VLOOKUP(D12,'Form Responses 1'!B:J,5,FALSE) -> Dacin | G12: =VLOOKUP(D12,'Form Responses 1'!B:J,6,FALSE) -> SNS | H12: =VLOOKUP(D12,'Form Responses 1'!B:J,7,FALSE) -> - | I12: =VLOOKUP(D12,'Form Responses 1'!B:J,8,FALSE) -> 211081 | J12: =VLOOKUP(D12,'Form Responses 1'!B:J,9,FALSE) -> 110 kg / 500 g | L12: SL4 (26) | M12: FALSE
D13: KPH KEDU SELATAN.. | E13: =VLOOKUP(D13,'Form Responses 1'!B:J,2,FALSE) -> Jl. A. Yani No 23 Purworejo | F13: =VLOOKUP(D13,'Form Responses 1'!B:J,5,FALSE) -> Dacin | G13: =VLOOKUP(D13,'Form Responses 1'!B:J,6,FALSE) -> SNS | H13: =VLOOKUP(D13,'Form Responses 1'!B:J,7,FALSE) -> - | I13: =VLOOKUP(D13,'Form Responses 1'!B:J,8,FALSE) -> 170694 | J13: =VLOOKUP(D13,'Form Responses 1'!B:J,9,FALSE) -> 110 kg / 500 g | L13: SL4 (26) | M13: FALSE
D14: KPH KEDU SELATAN... | E14: =VLOOKUP(D14,'Form Responses 1'!B:J,2,FALSE) -> Jl. A. Yani No 23 Purworejo | F14: =VLOOKUP(D14,'Form Responses 1'!B:J,5,FALSE) -> Dacin | G14: =VLOOKUP(D14,'Form Responses 1'!B:J,6,FALSE) -> SNS | H14: =VLOOKUP(D14,'Form Responses 1'!B:J,7,FALSE) -> - | I14: =VLOOKUP(D14,'Form Responses 1'!B:J,8,FALSE) -> 111724 | J14: =VLOOKUP(D14,'Form Responses 1'!B:J,9,FALSE) -> 110 kg / 500 g | L14: SL4 (26) | M14: FALSE
A15: 6 | B15: TS-001/I/500.2.3.15/10/2026 | C15: 46029 | D15: KPH KEDU SELATAN, | E15: =VLOOKUP(D15,'Form Responses 1'!B:J,2,FALSE) -> Jl. A. Yani No 23 Purworejo | F15: =VLOOKUP(D15,'Form Responses 1'!B:J,5,FALSE) -> Timbangan Sentisimal | G15: =VLOOKUP(D15,'Form Responses 1'!B:J,6,FALSE) -> Armada | H15: =VLOOKUP(D15,'Form Responses 1'!B:J,7,FALSE) -> - | I15: =VLOOKUP(D15,'Form Responses 1'!B:J,8,FALSE) -> 97815 | J15: =VLOOKUP(D15,'Form Responses 1'!B:J,9,FALSE) -> 500 kg / 200 g | K15: 46029 | L15: SP6 (26) | M15: TRUE
D16: KPH KEDU SELATAN,, | E16: =VLOOKUP(D16,'Form Responses 1'!B:J,2,FALSE) -> Jl. A. Yani No 23 Purworejo | F16: =VLOOKUP(D16,'Form Responses 1'!B:J,5,FALSE) -> Timbangan Sentisimal | G16: =VLOOKUP(D16,'Form Responses 1'!B:J,6,FALSE) -> Intra | H16: =VLOOKUP(D16,'Form Responses 1'!B:J,7,FALSE) -> - | I16: =VLOOKUP(D16,'Form Responses 1'!B:J,8,FALSE) -> - | J16: =VLOOKUP(D16,'Form Responses 1'!B:J,9,FALSE) -> 300 kg / 100 g | L16: SP6 (26) | M16: TRUE
D17: SPBU 44.543.04 PT. Tawakal Tsani Makmur.. | E17: =VLOOKUP(D17,'Form Responses 1'!B:J,2,FALSE) -> Jl. Yos Sudarso no 122, Desa Wero, Kec. Gombong, Kab. Kebumen | F17: =VLOOKUP(D17,'Form Responses 1'!B:J,5,FALSE) -> PU BBM | G17: =VLOOKUP(D17,'Form Responses 1'!B:J,6,FALSE) -> Wayne | H17: =VLOOKUP(D17,'Form Responses 1'!B:J,7,FALSE) -> 2203/Akswz5/E | I17: =VLOOKUP(D17,'Form Responses 1'!B:J,8,FALSE) -> G 07118 | J17: =VLOOKUP(D17,'Form Responses 1'!B:J,9,FALSE) -> - | L17: SP6 (26), JP8, H (np) | M17: TRUE
A18: 7 | B18: PU-001/I/500.2.3.15/11/2026 | C18: 46029 | D18: SPBU 44.543.04 PT. Tawakal Tsani Makmur | E18: =VLOOKUP(D18,'Form Responses 1'!B:J,2,FALSE) -> Jl. Yos Sudarso no 122, Desa Wero, Kec. Gombong, Kab. Kebumen | F18: =VLOOKUP(D18,'Form Responses 1'!B:J,5,FALSE) -> PU BBM | G18: =VLOOKUP(D18,'Form Responses 1'!B:J,6,FALSE) -> Gilbarco | H18: =VLOOKUP(D18,'Form Responses 1'!B:J,7,FALSE) -> B21 | I18: =VLOOKUP(D18,'Form Responses 1'!B:J,8,FALSE) -> HEPA 097853 | J18: =VLOOKUP(D18,'Form Responses 1'!B:J,9,FALSE) -> - | K18: 46029 | L18: SP6 (26), JP8, H (np) | M18: TRUE
D19: SPBU 44.543.04 PT. Tawakal Tsani Makmur. | E19: =VLOOKUP(D19,'Form Responses 1'!B:J,2,FALSE) -> Jl. Yos Sudarso no 122, Desa Wero, Kec. Gombong, Kab. Kebumen | F19: =VLOOKUP(D19,'Form Responses 1'!B:J,5,FALSE) -> PU BBM | G19: =VLOOKUP(D19,'Form Responses 1'!B:J,6,FALSE) -> Gilbarco | H19: =VLOOKUP(D19,'Form Responses 1'!B:J,7,FALSE) -> B21 | I19: =VLOOKUP(D19,'Form Responses 1'!B:J,8,FALSE) -> KDPA 028431 | J19: =VLOOKUP(D19,'Form Responses 1'!B:J,9,FALSE) -> - | L19: SP6 (26), JP8, H (np) | M19: TRUE
D20: SPBU 44.543.04 PT. Tawakal Tsani Makmur... | E20: =VLOOKUP(D20,'Form Responses 1'!B:J,2,FALSE) -> Jl. Yos Sudarso no 122, Desa Wero, Kec. Gombong, Kab. Kebumen | F20: =VLOOKUP(D20,'Form Responses 1'!B:J,5,FALSE) -> PU BBM | G20: =VLOOKUP(D20,'Form Responses 1'!B:J,6,FALSE) -> Gilbarco | H20: =VLOOKUP(D20,'Form Responses 1'!B:J,7,FALSE) -> B21 | I20: =VLOOKUP(D20,'Form Responses 1'!B:J,8,FALSE) -> HEPA 097463 | J20: =VLOOKUP(D20,'Form Responses 1'!B:J,9,FALSE) -> - | L20: SP6 (26), JP8, H (np) | M20: TRUE
A21: 8 | B21: TE-005/I/500.2.3.15/18/2026 | C21: 46031 | D21: Bank BSI Kebumen | E21: =VLOOKUP(D21,'Form Responses 1'!B:J,2,FALSE) -> Jl. HM Sarbini 201 A | F21: =VLOOKUP(D21,'Form Responses 1'!B:J,5,FALSE) -> Timbangan Elektronik | G21: =VLOOKUP(D21,'Form Responses 1'!B:J,6,FALSE) -> SHIMADZU | H21: =VLOOKUP(D21,'Form Responses 1'!B:J,7,FALSE) -> UX3200G | I21: =VLOOKUP(D21,'Form Responses 1'!B:J,8,FALSE) -> D461741786 | J21: =VLOOKUP(D21,'Form Responses 1'!B:J,9,FALSE) -> 3200 g/ 0,01 g | K21: 46030 | L21: SP6 (26) | M21: TRUE
A22: 9 | B22: PU-002/I/500.2.3.15/17/2026 | C22: 46031 | D22: SPBU 43.543.12 PT. Putra Ramadhan | E22: =VLOOKUP(D22,'Form Responses 1'!B:J,2,FALSE) -> Jl. HM Sarbini, Kelurahan Bumirejo, Kecamatan Kebumen, Kabupaten Kebumen | F22: =VLOOKUP(D22,'Form Responses 1'!B:J,5,FALSE) -> PU BBM | G22: =VLOOKUP(D22,'Form Responses 1'!B:J,6,FALSE) -> Gilbarco | H22: =VLOOKUP(D22,'Form Responses 1'!B:J,7,FALSE) -> NA1S500 | I22: =VLOOKUP(D22,'Form Responses 1'!B:J,8,FALSE) -> EN 00015183 | J22: =VLOOKUP(D22,'Form Responses 1'!B:J,9,FALSE) -> 60 Lpm / 5 lpm | K22: 46030 | L22: SP6 (26), JP8, H (np) | M22: TRUE
D23: SPBU 43.543.12 PT. Putra Ramadhan. | E23: =VLOOKUP(D23,'Form Responses 1'!B:J,2,FALSE) -> Jl. HM Sarbini, Kelurahan Bumirejo, Kecamatan Kebumen, Kabupaten Kebumen | F23: =VLOOKUP(D23,'Form Responses 1'!B:J,5,FALSE) -> PU BBM | G23: =VLOOKUP(D23,'Form Responses 1'!B:J,6,FALSE) -> Gilbarco | H23: =VLOOKUP(D23,'Form Responses 1'!B:J,7,FALSE) -> NA2 | I23: =VLOOKUP(D23,'Form Responses 1'!B:J,8,FALSE) -> AAEN240478 | J23: =VLOOKUP(D23,'Form Responses 1'!B:J,9,FALSE) -> 60 lpm / 5 lpm | L23: SP6 (26), JP8, H (np) | M23: TRUE
D24: SPBU 43.543.12 PT. Putra Ramadhan.. | E24: =VLOOKUP(D24,'Form Responses 1'!B:J,2,FALSE) -> Jl. HM Sarbini, Kelurahan Bumirejo, Kecamatan Kebumen, Kabupaten Kebumen | F24: =VLOOKUP(D24,'Form Responses 1'!B:J,5,FALSE) -> PU BBM | G24: =VLOOKUP(D24,'Form Responses 1'!B:J,6,FALSE) -> Gilbarco | H24: =VLOOKUP(D24,'Form Responses 1'!B:J,7,FALSE) -> NA2 | I24: =VLOOKUP(D24,'Form Responses 1'!B:J,8,FALSE) -> MXEN240026 | J24: =VLOOKUP(D24,'Form Responses 1'!B:J,9,FALSE) -> 60 lpm / 5 lpm | L24: SP6 (26), JP8, H (np) | M24: TRUE
D25: SPBU 43.543.12 PT. Putra Ramadhan... | E25: =VLOOKUP(D25,'Form Responses 1'!B:J,2,FALSE) -> Jl. HM Sarbini, Kelurahan Bumirejo, Kecamatan Kebumen, Kabupaten Kebumen | F25: =VLOOKUP(D25,'Form Responses 1'!B:J,5,FALSE) -> PU BBM | G25: =VLOOKUP(D25,'Form Responses 1'!B:J,6,FALSE) -> Gilbarco | H25: =VLOOKUP(D25,'Form Responses 1'!B:J,7,FALSE) -> NA1 | I25: =VLOOKUP(D25,'Form Responses 1'!B:J,8,FALSE) -> ABEN273664 | J25: =VLOOKUP(D25,'Form Responses 1'!B:J,9,FALSE) -> 60 lpm/5lpm | L25: SP6 (26), JP8, H (np) | M25: TRUE
A26: 10 | B26: TE-006/I/500.2.3.15/16/2026 | C26: 46031 | D26: Apotek Padureso | E26: =VLOOKUP(D26,'Form Responses 1'!B:J,2,FALSE) -> Jl. Wadaslintang km 17 Pasar pon, Padureso, Kebumen | F26: =VLOOKUP(D26,'Form Responses 1'!B:J,5,FALSE) -> Timbangan Elektronik | G26: =VLOOKUP(D26,'Form Responses 1'!B:J,6,FALSE) -> Acis | H26: =VLOOKUP(D26,'Form Responses 1'!B:J,7,FALSE) -> Bc500 | I26: =VLOOKUP(D26,'Form Responses 1'!B:J,8,FALSE) -> C220801736 | J26: =VLOOKUP(D26,'Form Responses 1'!B:J,9,FALSE) -> 500 g /0,1 g | L26: SL6 (26) | M26: TRUE
A27: 11 | B27: TE-007/I/500.2.3.15/15/2026 | C27: 46031 | D27: Toko Mas Niaga | E27: =VLOOKUP(D27,'Form Responses 1'!B:J,2,FALSE) -> Pasar Wonokriyo Blok F no. 14 Gombong Kebumen | F27: =VLOOKUP(D27,'Form Responses 1'!B:J,5,FALSE) -> Timbangan Elektronik | G27: =VLOOKUP(D27,'Form Responses 1'!B:J,6,FALSE) -> AND | H27: =VLOOKUP(D27,'Form Responses 1'!B:J,7,FALSE) -> HL-100 | I27: =VLOOKUP(D27,'Form Responses 1'!B:J,8,FALSE) -> K0003H2110724 | J27: =VLOOKUP(D27,'Form Responses 1'!B:J,9,FALSE) -> 100 g / 0.01 g | K27: 46030 | L27: SL6 (26) | M27: TRUE
D28: Toko Mas Niaga. | E28: =VLOOKUP(D28,'Form Responses 1'!B:J,2,FALSE) -> Pasar Wonokriyo Blok F no. 14 Gombong Kebumen | F28: =VLOOKUP(D28,'Form Responses 1'!B:J,5,FALSE) -> Timbangan Elektronik | G28: =VLOOKUP(D28,'Form Responses 1'!B:J,6,FALSE) -> AND | H28: =VLOOKUP(D28,'Form Responses 1'!B:J,7,FALSE) -> HL-100 | I28: =VLOOKUP(D28,'Form Responses 1'!B:J,8,FALSE) -> K0004H804001193 | J28: =VLOOKUP(D28,'Form Responses 1'!B:J,9,FALSE) -> 100 g / 0.01 g | M28: TRUE
D29: Toko Mas Niaga.. | E29: =VLOOKUP(D29,'Form Responses 1'!B:J,2,FALSE) -> Pasar Wonokriyo Blok F no. 14 Gombong Kebumen | F29: =VLOOKUP(D29,'Form Responses 1'!B:J,5,FALSE) -> Timbangan Elektronik | G29: =VLOOKUP(D29,'Form Responses 1'!B:J,6,FALSE) -> AND | H29: =VLOOKUP(D29,'Form Responses 1'!B:J,7,FALSE) -> EK-410i | I29: =VLOOKUP(D29,'Form Responses 1'!B:J,8,FALSE) -> 6A4443221 | J29: =VLOOKUP(D29,'Form Responses 1'!B:J,9,FALSE) -> 400 g / 0.01 g | M29: TRUE
A30: 12 | B30: TE-008/I/500.2.3.15/14/2026 | C30: 46031 | D30: Toko Mas Niaga, | E30: =VLOOKUP(D30,'Form Responses 1'!B:J,2,FALSE) -> Pasar Tumenggungan Blok A 9-10 kebumen | F30: =VLOOKUP(D30,'Form Responses 1'!B:J,5,FALSE) -> Timbangan Elektronik | G30: =VLOOKUP(D30,'Form Responses 1'!B:J,6,FALSE) -> AND | H30: =VLOOKUP(D30,'Form Responses 1'!B:J,7,FALSE) -> HT-120 | I30: =VLOOKUP(D30,'Form Responses 1'!B:J,8,FALSE) -> 5171100070 | J30: =VLOOKUP(D30,'Form Responses 1'!B:J,9,FALSE) -> 120 g / 0.01 g | K30: 46030 | L30: SL6 (26) | M30: TRUE
D31: Toko Mas Niaga,, | E31: =VLOOKUP(D31,'Form Responses 1'!B:J,2,FALSE) -> Pasar Tumenggungan Blok A 9-10 kebumen | F31: =VLOOKUP(D31,'Form Responses 1'!B:J,5,FALSE) -> Timbangan Elektronik | G31: =VLOOKUP(D31,'Form Responses 1'!B:J,6,FALSE) -> AND | H31: =VLOOKUP(D31,'Form Responses 1'!B:J,7,FALSE) -> EK-410i | I31: =VLOOKUP(D31,'Form Responses 1'!B:J,8,FALSE) -> 6A4443254 | J31: =VLOOKUP(D31,'Form Responses 1'!B:J,9,FALSE) -> 400 g / 0.01 g | M31: TRUE
A32: 13 | B32: TE-009/I/500.2.3.15/13/2026 | C32: 46031 | D32: Toko Mas Niaga' | E32: =VLOOKUP(D32,'Form Responses 1'!B:J,2,FALSE) -> Jln Yos Sudarso 331 Gombong | F32: =VLOOKUP(D32,'Form Responses 1'!B:J,5,FALSE) -> Timbangan Elektronik | G32: =VLOOKUP(D32,'Form Responses 1'!B:J,6,FALSE) -> AND | H32: =VLOOKUP(D32,'Form Responses 1'!B:J,7,FALSE) -> HT-120 | I32: =VLOOKUP(D32,'Form Responses 1'!B:J,8,FALSE) -> 5150900175 | J32: =VLOOKUP(D32,'Form Responses 1'!B:J,9,FALSE) -> 120 g / 0.01 g | K32: 46030 | L32: SL6 (26) | M32: TRUE
D33: Toko Mas Niaga'' | E33: =VLOOKUP(D33,'Form Responses 1'!B:J,2,FALSE) -> Jln Yos Sudarso 331 Gombong | F33: =VLOOKUP(D33,'Form Responses 1'!B:J,5,FALSE) -> Timbangan Elektronik | G33: =VLOOKUP(D33,'Form Responses 1'!B:J,6,FALSE) -> AND | H33: =VLOOKUP(D33,'Form Responses 1'!B:J,7,FALSE) -> HT-120 | I33: =VLOOKUP(D33,'Form Responses 1'!B:J,8,FALSE) -> 5210900407 | J33: =VLOOKUP(D33,'Form Responses 1'!B:J,9,FALSE) -> 120 g / 0.01 g | M33: TRUE
D34: Toko Mas Niaga''' | E34: =VLOOKUP(D34,'Form Responses 1'!B:J,2,FALSE) -> Jln Yos Sudarso 331 Gombong | F34: =VLOOKUP(D34,'Form Responses 1'!B:J,5,FALSE) -> Timbangan Elektronik | G34: =VLOOKUP(D34,'Form Responses 1'!B:J,6,FALSE) -> AND | H34: =VLOOKUP(D34,'Form Responses 1'!B:J,7,FALSE) -> EK-410i | I34: =VLOOKUP(D34,'Form Responses 1'!B:J,8,FALSE) -> 6A4443222 | J34: =VLOOKUP(D34,'Form Responses 1'!B:J,9,FALSE) -> 400 g / 0.01 g | M34: TRUE
A35: 14 | B35: TE-010/I/500.2.3.15/12/2026 | C35: 46031 | D35: Apotek Pandya 16 | E35: =VLOOKUP(D35,'Form Responses 1'!B:J,2,FALSE) -> Jatinegara , Sempor | F35: =VLOOKUP(D35,'Form Responses 1'!B:J,5,FALSE) -> Timbangan Elektronik | G35: =VLOOKUP(D35,'Form Responses 1'!B:J,6,FALSE) -> CHQ | H35: =VLOOKUP(D35,'Form Responses 1'!B:J,7,FALSE) -> DJ602C | I35: =VLOOKUP(D35,'Form Responses 1'!B:J,8,FALSE) -> 0 | J35: =VLOOKUP(D35,'Form Responses 1'!B:J,9,FALSE) -> 600 gr/0,01 gr | K35: 46030 | L35: SL6 (26) | M35: TRUE
A36: 15 | B36: PU-003/I/500.2.3.15/22/2026 | C36: 46034 | D36: SPBU 44.543.22 (PT. Wahyu Putra Sejati) | E36: =VLOOKUP(D36,'Form Responses 1'!B:J,2,FALSE) -> Desa Tambakmulyo, Kecamatan Puring, Kabupaten Kebumen | F36: =VLOOKUP(D36,'Form Responses 1'!B:J,5,FALSE) -> PU BBM | G36: =VLOOKUP(D36,'Form Responses 1'!B:J,6,FALSE) -> TATSUNO | H36: =VLOOKUP(D36,'Form Responses 1'!B:J,7,FALSE) -> SSB3662 | I36: =VLOOKUP(D36,'Form Responses 1'!B:J,8,FALSE) -> AA315408 2022-1 | J36: =VLOOKUP(D36,'Form Responses 1'!B:J,9,FALSE) -> 65 L/min | K36: 46031 | L36: SP6 (26), H (np), JP8 | M36: TRUE
A37: 16 | B37: PU-004/I/500.2.3.15/21/2026 | C37: 46034 | D37: SPBU 44.543.10 (CV. Dewi Bulan) | E37: =VLOOKUP(D37,'Form Responses 1'!B:J,2,FALSE) -> Jl. Lingkar Soka, Desa Kewayuhan, Kecamatan Pejagoan, Kabupaten Kebumen | F37: =VLOOKUP(D37,'Form Responses 1'!B:J,5,FALSE) -> PU BBM | G37: =VLOOKUP(D37,'Form Responses 1'!B:J,6,FALSE) -> TATSUNO | H37: =VLOOKUP(D37,'Form Responses 1'!B:J,7,FALSE) -> GSB 2441P | I37: =VLOOKUP(D37,'Form Responses 1'!B:J,8,FALSE) -> AA 192403 2010-6 | J37: =VLOOKUP(D37,'Form Responses 1'!B:J,9,FALSE) -> 60 L/min | K37: 46031 | L37: SP6 (26), H (np), JP8 | M37: TRUE
D38: SPBU 44.543.10 (CV. Dewi Bulan), | E38: =VLOOKUP(D38,'Form Responses 1'!B:J,2,FALSE) -> Jl. Lingkar Soka, Desa Kewayuhan, Kecamatan Pejagoan, Kabupaten Kebumen | F38: =VLOOKUP(D38,'Form Responses 1'!B:J,5,FALSE) -> PU BBM | G38: =VLOOKUP(D38,'Form Responses 1'!B:J,6,FALSE) -> TATSUNO | H38: =VLOOKUP(D38,'Form Responses 1'!B:J,7,FALSE) -> GSB 2441P | I38: =VLOOKUP(D38,'Form Responses 1'!B:J,8,FALSE) -> AA 199109 2011-3 | J38: =VLOOKUP(D38,'Form Responses 1'!B:J,9,FALSE) -> 60 L/min | M38: TRUE
D39: SPBU 44.543.10 (CV. Dewi Bulan),, | E39: =VLOOKUP(D39,'Form Responses 1'!B:J,2,FALSE) -> Jl. Lingkar Soka, Desa Kewayuhan, Kecamatan Pejagoan, Kabupaten Kebumen | F39: =VLOOKUP(D39,'Form Responses 1'!B:J,5,FALSE) -> PU BBM | G39: =VLOOKUP(D39,'Form Responses 1'!B:J,6,FALSE) -> TATSUNO | H39: =VLOOKUP(D39,'Form Responses 1'!B:J,7,FALSE) -> GSA 1221 | I39: =VLOOKUP(D39,'Form Responses 1'!B:J,8,FALSE) -> AA 166702 2007-10 | J39: =VLOOKUP(D39,'Form Responses 1'!B:J,9,FALSE) -> 60 L/min | M39: TRUE
D40: SPBU 44.543.10 (CV. Dewi Bulan),,, | E40: =VLOOKUP(D40,'Form Responses 1'!B:J,2,FALSE) -> Jl. Lingkar Soka, Desa Kewayuhan, Kecamatan Pejagoan, Kabupaten Kebumen | F40: =VLOOKUP(D40,'Form Responses 1'!B:J,5,FALSE) -> PU BBM | G40: =VLOOKUP(D40,'Form Responses 1'!B:J,6,FALSE) -> TATSUNO | H40: =VLOOKUP(D40,'Form Responses 1'!B:J,7,FALSE) -> GSB 2441P | I40: =VLOOKUP(D40,'Form Responses 1'!B:J,8,FALSE) -> AA 185772 2009-9 | J40: =VLOOKUP(D40,'Form Responses 1'!B:J,9,FALSE) -> 60 L/min | M40: TRUE
...

Sheet Analisis
A1: Jenis UTTP | B1: Bulan
A2: Timbangan Elektronik | B2: Januari
A3: Timbangan Elektronik | B3: Januari
A4: Timbangan Elektronik | B4: Januari
A5: Timbangan Elektronik | B5: Januari
A6: Timbangan Elektronik | B6: Januari
A7: Timbangan Elektronik | B7: Januari
A8: Timbangan Elektronik | B8: Januari
A9: Timbangan Elektronik | B9: Januari
A10: PU BBM | B10: Januari
A11: PU BBM | B11: Januari
A12: Dacin | B12: Januari
... A363: Timbangan Elektronik | B363: Juli

Sheet NVScriptsProperties
A1: autocratn | B1: autocratp
A2: dataSheetName | B2: "Form Responses 1"
A3: v | B3: "5.1"
A4: dataSheetId | B4: "1.689868182E9"
A5: updateTime | B5: "1.780016951083E12"
A6: vp | B6: "5.1"
A7: ssId | B7: "1Q7eYM-0OaR3yipkffl29x8iKtPYfGH8IDzDvPTVYEe4"

Sheet DO NOT DELETE - AutoCrat Job Se
A1: Job ID | B1: Job Name | C1: Template ID | D1: Data Sheet ID | E1: Header Row | F1: First Data Row | G1: File Name | H1: File Type | I1: Share As | J1: Folders | K1: Dynamic Folder Reference | L1: Conditionals | M1: Mode | N1: Append Breaks | O1: Tags | P1: Run On Time Trigger | Q1: Time Trigger Frequency | R1: Run On Form Trigger | S1: Send Email And Share | T1: Email To | U1: Email CC | V1: Email BCC | W1: Email Reply To | X1: Email No Reply | Y1: Email Subject | Z1: Email Body | AA1: Prevent Resharing | AB1: Time Trigger Timestamp | AC1: Form Trigger Timestamp
A2: _1766454756496 | B2: AutoCrat Demo Job | C2: 1AkuWiPbtXLR_HqaguT82EnK3Og1XcN2IxNsUDlaBnOs | D2: 1929054279 | E2: 1 | F2: 2 | G2: Demo merge job run on <<NOW>> | H2: GOOG_DOC | I2: EDITABLE | J2: ["1ZUpARtCkyT-m-NGzjfxq5qkm8cqqIHRA"] | K2: [] | L2: [] | M2: MULTIPLE_OUTPUT | O2: [{"tag":"Image URL","type":"IMAGE","details":{"headerMap":"Image URL","imageHeight":"<<Image Height>>","imageWidth":"<<Image Width>>"}},{"tag":"Image description","type":"STANDARD","details":{"headerMap":"Image description"}},{"tag":"Cloudlab URL","type":"LINK","details":{"headerMap":"Cloudlab URL","linkLabel":"Cloudlab"}},{"tag":"New Visions URL","type":"LINK","details":{"headerMap":"New Visions URL","linkLabel":"<<NVPS Link Label>>"}},{"tag":"TODAY","type":"BONUS","details":{}},{"tag":"TODAY","type":"BONUS","details":{}}] | P2: FALSE | R2: FALSE | S2: TRUE | T2: metrologikebumen@gmail.com | X2: FALSE | Y2: AutoCrat Demo Merge run on <<TODAY>> | Z2: Your document is ready! <<Closing>> | AA2: FALSE
